<?xml version="1.0" ?>
<sdf version="1.6">
  <world name="default">
    <gui>
      <camera name="user_camera">
        <pose>-5 0 1 0 0.2 0</pose>
        <view_controller>orbit</view_controller>
        <projection_type>perspective</projection_type>
      </camera>
    </gui>
    <physics type="ode">
      <ode>
        <solver>
          <type>quick</type>
          <iters>100</iters>
          <sor>1.0</sor>
        </solver>
        <constraints>
          <cfm>0.0</cfm>
          <erp>0.2</erp>
          <contact_max_correcting_vel>0.1</contact_max_correcting_vel>
          <contact_surface_layer>0.0</contact_surface_layer>
        </constraints>
      </ode>
      <real_time_update_rate>-1</real_time_update_rate>
      <!--<max_step_size>0.0020</max_step_size>-->
    </physics>
    <gravity>0 0 -9.8</gravity>
    <include>
      <uri>model://sun</uri>
    </include>

    <model name="ground_plane">
      <static>true</static>
      <link name="link">
        <collision name="collision">
          <geometry>
            <plane>
              <normal>0 0 1</normal>
              <size>5000 5000</size>
            </plane>
          </geometry>
          <surface>
            <friction>
              <ode>
                <mu>100</mu>
                <mu2>50</mu2>
              </ode>
            </friction>
          </surface>
        </collision>
        <visual name="runway">
          <pose>000 0 0.005 0 0 0</pose>
          <cast_shadows>false</cast_shadows>
          <geometry>
            <plane>
              <normal>0 0 1</normal>
              <size>1829 45</size>
            </plane>
          </geometry>
          <material>
            <script>
              <uri>file://media/materials/scripts/gazebo.material</uri>
              <name>Gazebo/Runway</name>
            </script>
          </material>
        </visual>

        <visual name="grass">
          <pose>0 0 -0.1 0 0 0</pose>
          <cast_shadows>false</cast_shadows>
          <geometry>
            <plane>
              <normal>0 0 1</normal>
              <size>5000 5000</size>
            </plane>
          </geometry>
          <material>
            <script>
              <uri>file://media/materials/scripts/gazebo.material</uri>
              <name>Gazebo/Grass</name>
            </script>
          </material>
        </visual>

      </link>
    </model>

    <include>
      <uri>model://hacker_van</uri>
      <pose>4.34581 -6.72978 0.05 0 -0 0.7586</pose>
    </include>

    <include>
      <uri>model://hacker_desk</uri>
      <pose>3.73953 -3.3219 0.001958 0 0 -0.756161</pose>
    </include>

    <include>
      <uri>model://gcs_table</uri>
      <pose>-4 0 0 0 -0 0</pose>
    </include>

    <include><projection_type>perspective</projection_type>
      <uri>model://operator</uri>
      <pose>-4.74585 -0.010506 -0.145856 0 -0 1.65382</pose>
    </include>

    <include>
      <uri>model://gcs_chair</uri>
      <pose>-4.41943 -0.415139 0 0 -0 1.68293</pose>
    </include>

    <include>
      <uri>model://laptop</uri>
      <pose>-4.04083 -0.118429 0.809145 0 0 -1.90525</pose>
    </include>

    <model name="iris_demo">
      <include>
        <uri>model://iris_with_ardupilot</uri>
      </include>
    <!-- add new camera -->
      <link name='camera'>
        <pose>0 -0.01 0.070 .8 0 1.57</pose>
        <inertial>
          <pose>0 0 0 0 0 0</pose>
          <mass>0.1</mass>
          <inertia>
            <ixx>0.001</ixx>
            <ixy>0</ixy>
            <ixz>0</ixz>
            <iyy>0.001</iyy>
            <iyz>0</iyz>
            <izz>0.001</izz>
          </inertia>
        </inertial>
        <visual name='visual'>
          <pose>0 0 0 0 0 0</pose>
          <geometry>
            <cylinder>
              <radius>0.025</radius>
              <length>0.025</length>
            </cylinder>
          </geometry>
           <material>
            <script>
              <uri>file://media/materials/scripts/gazebo.material</uri>
              <name>Gazebo/Grey</name>
            </script>
          </material>
        </visual>

        <sensor name="camera" type="camera">
          <pose>0 0 0 -1.57 -1.57 0</pose>
          <camera>
            <horizontal_fov>1.0472</horizontal_fov>
            <image>
              <width>640</width>
              <height>480</height>
            </image>
            <clip>
              <near>0.05</near>
              <far>1000</far>
            </clip>
          </camera>
          <always_on>1</always_on>
          <update_rate>10</update_rate>
          <visualize>true</visualize>

         <!--  <plugin name="irlock" filename="libArduCopterIRLockPlugin.so">
              <fiducial>irlock_beacon_01</fiducial>
          </plugin> -->
          <plugin name="camera_controller" filename="libgazebo_ros_camera.so">
          <alwaysOn>true</alwaysOn>
          <updateRate>0.0</updateRate>
          <cameraName>webcam</cameraName>
          <imageTopicName>image_raw</imageTopicName>
          <cameraInfoTopicName>camera_info</cameraInfoTopicName>
          <frameName>camera_link</frameName>
          <hackBaseline>0.07</hackBaseline>
          <distortionK1>0.0</distortionK1>
          <distortionK2>0.0</distortionK2>
          <distortionK3>0.0</distortionK3>
          <distortionT1>0.0</distortionT1>
          <distortionT2>0.0</distortionT2>
      </plugin>

        </sensor>

      </link>

      <!-- attach camera -->
      <joint type="revolute" name="base_camera_joint">
        <pose>0 0 0.0 0 0 0</pose>
        <parent>iris_demo::gimbal_small_2d::tilt_link</parent>
        <child>iris_demo::camera</child>
        <axis>
          <xyz>0 0 1</xyz>
          <limit>
            <lower>-0.5</lower>
            <upper>0.5</upper>
            <effort>10</effort>
            <velocity>10</velocity>
          </limit>
          <dynamics>
            <damping>0.1</damping>
          </dynamics>
          <use_parent_model_frame>true</use_parent_model_frame>
        </axis>
      </joint>
    </model>
  </world>
</sdf>